<?xml version="1.0"?>
<robot xmlns:xacro="http://www.ros.org/wiki/xacro" name="test_robot">

    <!-- Define enertial and material properties -->
    <xacro:include filename="properties.xacro"/>

    <!-- CHASSIS LINK -->
    <link name="chassis">

        <collision name='collision'>
            <origin xyz="0 0 0.1" rpy="0 0 0"/>
            <geometry>
                <box size=".4 .2 .1"/>
            </geometry>
        </collision>
        <visual name='visual'>
            <origin xyz="0 0 0.1" rpy="0 0 0"/>
            <geometry>
                <box size=".4 .2 .1"/>
            </geometry>
            <material name="white"/>
        </visual>

        <collision name='caster_collision'>
            <origin xyz="-0.15 0 -0.05" rpy="0 0 0"/>
            <geometry>
                <sphere radius="0.05"/>
            </geometry>
        </collision>
        <visual name='caster_visual'>
            <origin xyz="-0.15 0 -0.05" rpy="0 0 0"/>
            <geometry>
                <sphere radius="0.05"/>
            </geometry>
            <material name="white">
        </visual>

        <xacro:inertial_box mass="1.0" x="0.4" y="0.2" z="0.1">
            <origin xyz="0 0 0.1" rpy="0 0 0"/>
        </xacro:inertial_box>

    </link>
    
    <!-- LEFT WHEEL LINK -->
    <link name="left_wheel">

        <collision name='collision'>
            <origin xyz="0.1 0.13 0.1" rpy="0 1.5707 1.5707"/>
            <geometry>
                <cylinder radius="0.1" length="0.05"/>
            </geometry>
        </collision>
        <visual name='visual'>
            <origin xyz="0.1 0.13 0.1" rpy="0 1.5707 1.5707"/>
            <geometry>
                <cylinder radius="0.1" length="0.05"/>
            </geometry>
            <material name="blue"/>
        </visual>

        <xacro:inertial_cylinder mass="0.25" length="0.05" radius="0.1">
            <origin xyz="0.1 0.13 0.1" rpy="0 1.5707 1.5707"/>
        </xacro:inertial_cylinder>
        
    </link>

    <!-- RIGHT WHEEL LINK -->
    <link name="right_wheel">
        
        <collision name='collision'>
            <origin xyz="0.1 -0.13 0.1" rpy="0 1.5707 1.5707"/>
            <geometry>
                <cylinder radius="0.1" length="0.05"/>
            </geometry>
        </collision>
        <visual name='visual'>
            <origin xyz="0.1 -0.13 0.1" rpy="0 1.5707 1.5707"/>
            <geometry>
                <cylinder radius="0.1" length="0.05"/>
            </geometry>
            <material name="blue">
        </visual>

        <xacro:inertial_cylinder mass="0.25" length="0.05" radius="0.1">
            <origin xyz="0.1 -0.13 0.1" rpy="0 1.5707 1.5707"/>
        </xacro:inertial_cylinder>
        
    </link>

    <!-- LEFT WHEEL JOINT -->
    <joint name="left_wheel_hinge" type="continuous">
        <origin xyz="0 0 -0.03" rpy="0 0 0"/>
        <parent link="chassis"/>
        <child link="left_wheel"/>
        <axis xyz="0 1 0"/>
    </joint>

    <!-- RIGHT WHEEL JOINT -->
    <joint name="right_wheel_hinge" type="continuous">
        <origin xyz="0 0 0.03" rpy="0 0 0"/>
        <parent link="chassis"/>
        <child link="right_wheel"/>
        <axis xyz="0 1 0"/>
    </joint>

    <xacro:include filename="properties.xacro"/>

</robot>
